Workbook

Sheet Lists
A1: Dropdown lists and lookup tables. Formulas on other sheets point at these ranges - do not reorder or insert rows.
A2: Status | B2: Stage 1 category | C2: Q1 What starts it | D2: Q2 Where it lands | E2: Q2b Connectivity | F2: Q3 Reach | G2: Q4 Permissions | H2: Q5 Data class | I2: Q6 Know or do | J2: Q7 Connection | K2: Q8a Wrong answer | L2: Q8b Silent failure | M2: Yes / No | N2: Assurance tier | O2: Verb | P2: Benefit type | Q2: Hard or soft | R2: Gate status | S2: Ladder rung | T2: Owning team | U2: Phase | V2: Agent shape
A3: Not started | B3: Automation | C3: A person asks | D3: No interface | E3: Always connected | F3: 1 Me | G3: Acts as the user | H3: Public | I3: Nothing | J3: Yes, in production | K3: Read only | L3: Nothing | M3: Yes | N3: Light touch | O3: Assist | P3: Time or cost released | Q3: Hard | R3: Not met | S3: 1 Not AI | T3: Platform team | U3: a Interim | V3: Single agent
A4: In discovery | B4: Predictive or optimisation | C4: A person is already working | D4: Inside the tool they have open | E4: Intermittent | F4: 2 My team | G4: Acts as itself (service identity) | H4: Internal | I4: Static documents | J4: Yes, but not to this system | K4: Writes to a system | L4: Work is delayed | M4: No | N4: Owner approves | O4: Delegate | P4: Error and rework reduction | Q4: Soft | R4: In progress | S4: 2 Ready-made | T4: Workload team | U4: b Target | V4: Multi-agent: compliance boundary
A5: Contract agreed | B5: Retrieval | C5: A system event | D5: Collaboration surface | E5: Must work offline | F5: 3 Function | H5: Confidential | I5: Analytical data | J5: No | K5: Real-world effect | L5: A person is affected | M5: Unknown | N5: Controlled pilot | O5: Monitor | P5: Speed and responsiveness | Q5: Hard or soft | R5: Met | S5: 3 Low-code | T5: AI Centre of Excellence | U5: Single | V5: Multi-agent: multiple teams
A6: Scored | B6: LLM-augmented workflow | C6: A schedule | D6: Embedded in a line of business app | E6: Not applicable | F6: 4 Enterprise | H6: Regulated | I6: Live system state | N6: Full assurance | O6: Specialize | P6: Risk and compliance avoided | R6: Not applicable | S6: 4 Pro-code | T6: Partner | V6: Multi-agent: planned growth
A7: Approved | B7: Agent | C7: Another agent | D7: Frontline device | F7: 5 External | I7: Take an action | O7: Control | P7: Capacity redirected to the mission | S7: 5 Infrastructure
A8: Building | D8: External channel | O8: Adapt | P8: Experience and retention
A9: Piloting | O9: Act locally
A10: Released | O10: Build
A11: Parked
A12: Rejected
A30: Stage 4 - assurance tier matrix (consequence x reach). Header row 31, data rows 32-34.
A31: Q8a consequence | B31: 1-2 | C31: 3 | D31: 4-5
A32: Read only | B32: Light touch | C32: Owner approves | D32: Controlled pilot
A33: Writes to a system | B33: Owner approves | C33: Controlled pilot | D33: Full assurance
A34: Real-world effect | B34: Controlled pilot | C34: Full assurance | D34: Full assurance
A35: Tier ordinals. Data rows 37-40.
A36: Tier | B36: Ordinal | C36: What it means
A37: Light touch | B37: 1 | C37: Ship it. Standard guardrails only.
A38: Owner approves | B38: 2 | C38: Named owner signs off. Spot-checked, not gated.
A39: Controlled pilot | B39: 3 | C39: Measured pilot, defined success criteria, a decision gate.
A40: Full assurance | B40: 4 | C40: Evaluations, human in the loop, monitoring, a route to a person.
A41: Stage 5 level 2 - the eight verbs. Data rows 43-50.
A42: Verb | B42: Lands on | C42: Selected by
A43: Assist | B43: Microsoft 365 Copilot | C43: Q1 person already working - Q2 inside the tool they have open - Q8a read only
A44: Delegate | B44: Copilot Cowork | C44: Q1 person asks - Q6 take an action across several M365 surfaces - returns a finished artefact
A45: Monitor | B45: Fabric operations agent | C45: Q1 system event or schedule - Q6 live system state - Q2 no interface, output arrives in Teams
A46: Specialize | B46: Declarative agent / Agent Builder | C46: Q1 person asks - Q6 static documents - Q3 team or function - stable scope
A47: Control | B47: Copilot Studio, standard harness | C47: Q8a writes to a system - consistency and branching matter - analytics and channel publishing
A48: Adapt | B48: Copilot Studio, GitHub Copilot harness | C48: Reasoning-heavy - multi-tool - document-intensive - the path is not fixed
A49: Act locally | B49: Microsoft Scout | C49: Q2 local files, shell or browser - Q5 data that should not leave the device
A50: Build | B50: Microsoft Foundry (+ Foundry Local) | C50: Q3 tier 4-5 - Q5 regulated - Q8a real-world effect - needs evaluation, tracing, VNet
A51: Q5 - what each data class forces. Data rows 53-56.
A52: Answer | B52: What it forces
A53: Public | B53: Must not touch internal sources. Separate environment from internal agents.
A54: Internal | B54: Standard M365 or Foundry standard setup, public networking. Labels honoured.
A55: Confidential | B55: Foundry standard with private networking, or Copilot Studio with data location set. Explicit DLP policy. Named retention period.
A56: Regulated | B56: All of the above, plus consent and residency answered before build, plus retention and deletion mechanisms, plus a named accountable human.
A57: Stage 4 - release gate, the three tests behind each check.
...

Sheet Start here
B2: AI use case decision workbook - WORKED SAMPLE
B3: Two illustrative rows, filled in end to end, so the method can be read without a customer in the room. Every name, number and system is invented. UC-01 is what a genuine quick win looks like. UC-02 is what one does not, and the workbook says why in each column rather than just asserting it. Delete both rows to use this as a live workbook.
B5: How to use it
B6: One row per job | C6: Row 3 on every sheet is the same use case as row 3 on every other sheet. Split vague labels into jobs before you start: one label often covers three or four jobs, each with a different risk profile and a different owner. Phase a use case with a shared ID and the Phase column - UC-06a interim, UC-06b target - and score each phase separately.
B7: Cream cells are yours | C7: Cream cells are inputs. Blue-grey italic cells are calculated - do not type in them.
B8: Work left to right | C8: Register, then Outcome contract, then Eight questions. Assurance and gate, Technology direction and Answers out then fill themselves in.
B9: Blanks are the deliverable | C9: The value baseline and owner cells are usually the emptiest in the workbook and only the customer can fill them. A named, specific list of what is missing is a more useful deliverable than a set of confident guesses. The last column of Answers out builds that list per row automatically.
B11: The eight stages
B12: Stage 0 - Business plan for AI agents | C12: Frame the list. Desirability, feasibility, viability, responsibility. Split vague labels into jobs, deduplicate, allow phasing.
B13: Stage 1 - Is this AI at all? | C13: Four outcomes and only one is an agent: automation, predictive, LLM-augmented, agent, with retrieval alongside as the light case. The highest-value gate in the framework for saving money.
B14: Stage 2 - The outcome contract | C14: The result, the owner, the boundary, the gates, the value baseline. Five things, all before anyone opens a product page.
B15: Stage 3 - The eight questions | C15: None of them names a product. Answer them and the platform, retrieval pattern, identity model, network topology and assurance bar are already determined.
B16: Stage 4 - Assurance tier and release gate | C16: Consequence by reach sets the tier. Q8b lifts it. Regulated data floors it. Then six checks: accountable, identifiable, constrained, tested, observable, recoverable.
B17: Stage 5 - Technology direction | C17: Prefer the lowest rung that works, and read assurance before category. Low-code supports autonomous agents - do not climb a rung you do not need.
B18: Stage 6 - Prove it | C18: Prototype time-boxed, pilot the hardest step, evaluate against the Stage 2 measure, red team, release only once the control has run for real.
B19: Stage 7 - Operate | C19: Monitor the outcome measure not uptime, re-evaluate on a schedule, keep the control staffed, name the back-to-design triggers, audit the estate.
B21: The sheets
B22: Register | C22: Identity, Stage 0 scores, Stage 1 category, and the rollup of every calculated answer.
B23: Outcome contract | C23: Stage 2. The five contract items and the six value baseline measurements.
B24: Eight questions | C24: Stage 3. Q1 to Q8b, plus intended versus pilot reach and the connectivity assumption.
B25: Assurance and gate | C25: Stage 4. Calculated tier with the working shown, then the six-point release gate.
B26: Technology direction | C26: Stage 5. Calculated ladder rung, suggested verb, landing product, run-location constraints.
B27: Prove and operate | C27: Stages 6 and 7. Prototype, evaluation, red team, release, then the run obligations.
B28: Answers out | C28: The eight columns the customer asked for, produced from the stages above.
B29: Scoring | C29: The Cloud Adoption Framework's nine sub-criteria, three axes, 1 to 5.
B30: Lists | C30: Dropdown lists and lookup tables. Formulas point at these ranges - do not reorder.
B31: Decision logic | C31: How every calculated column is derived, in words.
B32: Platform reference | C32: The seven surfaces, what they run on, what they are best for.
B33: References | C33: Cloud Adoption Framework sources, per stage.
B35: Version and status
B36: What this is | C36: An independent decision framework and the author's own professional recommendations. It builds on publicly available Microsoft Cloud Adoption Framework guidance, which is linked at each stage. It is NOT official Microsoft guidance, NOT a Microsoft product, and NOT supported by Microsoft.
B37: Not professional advice | C37: Nothing here is legal, regulatory, clinical, privacy or financial advice. The assurance tiers and governance positions are the author's recommendations, not a compliance standard. Validate against your own obligations and take professional advice where those obligations apply.
B38: No commercial terms | C38: This workbook deliberately carries no licensing, pricing or entitlement information. Those are customer-specific, move quarterly, and are not this framework's to state. Confirm licensing, preview status and regional availability with Microsoft before any recommendation.
B39: Product claims | C39: The framework names capabilities. Where the workbook names a product, treat it as current-as-checked and confirm before rollout.
B40: No warranty | C40: Provided as is, without warranty of any kind. You are responsible for decisions made using it.
B41: Generated | C41: 2026-09-10

Sheet Register
A1: IDENTITY | J1: STAGE 0 BUSINESS PLAN (1-5 each) | O1: STAGE 1 IS THIS AI AT ALL? | W1: ROLLUP (calculated)
A2: ID | B2: Phase | C2: Use case (one job, one owner, one risk profile) | D2: What it actually does, in one sentence | E2: Business area | F2: Requested by | G2: Status | H2: Date reviewed | I2: Duplicate of / related to | J2: Desirability | K2: Feasibility | L2: Viability | M2: Responsibility (1-5) | N2: Stage 0 total (of 20) | O2: Language or judgement needed? | P2: Forecasting, scoring or matching? | Q2: Multi-step decisions? | R2: Many tools or systems? | S2: Adaptive to messy input? | T2: Suggested category | U2: Category (confirmed) | V2: Route if it is not an agent | W2: Assurance tier | X2: Ladder rung | Y2: Lands on | Z2: Time estimate | AA2: Quick win? | AB2: Contract complete
A3: UC-01 | B3: Single | C3: Policy and procedure assistant | D3: Answers staff questions about internal policy by searching the approved policy library on SharePoint, and quotes the source document in every answer. | E3: People and Culture | F3: A. Whitfield, Head of P&C Operations | G3: Approved | H3: 46268.583 | J3: =IF(Scoring!N3="","",ROUND(Scoring!N3/3,1)) | K3: =IF(Scoring!M3="","",ROUND(Scoring!M3/3,1)) | L3: =IF(Scoring!L3="","",ROUND(Scoring!L3/3,1)) | M3: 5 | N3: =IF(COUNT(J3:M3)<4,"",SUM(J3:M3)) | O3: Yes | P3: No | Q3: No | R3: No | S3: No | T3: =IF(COUNTBLANK(O3:S3)>0,"",IF(P3="Yes","Predictive or optimisation",IF(O3="No","Automation",IF(AND(Q3="Yes",R3="Yes",S3="Yes"),"Agent",IF(AND(Q3="No",R3="No"),"Retrieval","LLM-augmented workflow"))))) | U3: Retrieval | V3: =IF(U3="","",IF(U3="Automation","Power Automate, Logic Apps or code. No AI governance.",IF(U3="Predictive or optimisation","Fabric data science, Azure ML or a prebuilt Foundry model. Model governance, not agent governance.",IF(U3="Retrieval","SharePoint agent, Copilot Studio retrieval agent or classic RAG. Light governance.",IF(U3="LLM-augmented workflow","A flow with one AI action, or a scheduled prompt. Governance proportional to consequence.","Agent. Continue to Stage 2."))))) | W3: =IF('Assurance and gate'!K3="","",'Assurance and gate'!K3) | X3: =IF(IF('Technology direction'!D3="",'Technology direction'!C3,'Technology direction'!D3)="","",IF('Technology direction'!D3="",'Technology direction'!C3,'Technology direction'!D3)) | Y3: =IF('Technology direction'!H3="","",'Technology direction'!H3) | Z3: =IF('Answers out'!K3="","",'Answers out'!K3) | AA3: =IF('Answers out'!C3="","",'Answers out'!C3) | AB3: =IF('Answers out'!N3="","",'Answers out'!N3)
A4: UC-02 | B4: Single | C4: Clinical visit scribe | D4: A care worker speaks a summary at the end of a home visit; the agent drafts the clinical progress note, files it against the client record, and flags anything a clinician needs to review. | E4: Clinical Services | F4: Dr M. Ferreira, Clinical Director | G4: In discovery | H4: 46273.583 | I4: Related to UC-01 only in that both were labelled "an AI assistant" on the original list. Split at Stage 0. | J4: =IF(Scoring!N4="","",ROUND(Scoring!N4/3,1)) | K4: =IF(Scoring!M4="","",ROUND(Scoring!M4/3,1)) | L4: =IF(Scoring!L4="","",ROUND(Scoring!L4/3,1)) | M4: 3 | N4: =IF(COUNT(J4:M4)<4,"",SUM(J4:M4)) | O4: Yes | P4: No | Q4: Yes | R4: Yes | S4: Yes | T4: =IF(COUNTBLANK(O4:S4)>0,"",IF(P4="Yes","Predictive or optimisation",IF(O4="No","Automation",IF(AND(Q4="Yes",R4="Yes",S4="Yes"),"Agent",IF(AND(Q4="No",R4="No"),"Retrieval","LLM-augmented workflow"))))) | U4: Agent | V4: =IF(U4="","",IF(U4="Automation","Power Automate, Logic Apps or code. No AI governance.",IF(U4="Predictive or optimisation","Fabric data science, Azure ML or a prebuilt Foundry model. Model governance, not agent governance.",IF(U4="Retrieval","SharePoint agent, Copilot Studio retrieval agent or classic RAG. Light governance.",IF(U4="LLM-augmented workflow","A flow with one AI action, or a scheduled prompt. Governance proportional to consequence.","Agent. Continue to Stage 2."))))) | W4: =IF('Assurance and gate'!K4="","",'Assurance and gate'!K4) | X4: =IF(IF('Technology direction'!D4="",'Technology direction'!C4,'Technology direction'!D4)="","",IF('Technology direction'!D4="",'Technology direction'!C4,'Technology direction'!D4)) | Y4: =IF('Technology direction'!H4="","",'Technology direction'!H4) | Z4: =IF('Answers out'!K4="","",'Answers out'!K4) | AA4: =IF('Answers out'!C4="","",'Answers out'!C4) | AB4: =IF('Answers out'!N4="","",'Answers out'!N4)
J5: =IF(Scoring!N5="","",ROUND(Scoring!N5/3,1)) | K5: =IF(Scoring!M5="","",ROUND(Scoring!M5/3,1)) | L5: =IF(Scoring!L5="","",ROUND(Scoring!L5/3,1)) | N5: =IF(COUNT(J5:M5)<4,"",SUM(J5:M5)) | T5: =IF(COUNTBLANK(O5:S5)>0,"",IF(P5="Yes","Predictive or optimisation",IF(O5="No","Automation",IF(AND(Q5="Yes",R5="Yes",S5="Yes"),"Agent",IF(AND(Q5="No",R5="No"),"Retrieval","LLM-augmented workflow"))))) | V5: =IF(U5="","",IF(U5="Automation","Power Automate, Logic Apps or code. No AI governance.",IF(U5="Predictive or optimisation","Fabric data science, Azure ML or a prebuilt Foundry model. Model governance, not agent governance.",IF(U5="Retrieval","SharePoint agent, Copilot Studio retrieval agent or classic RAG. Light governance.",IF(U5="LLM-augmented workflow","A flow with one AI action, or a scheduled prompt. Governance proportional to consequence.","Agent. Continue to Stage 2."))))) | W5: =IF('Assurance and gate'!K5="","",'Assurance and gate'!K5) | X5: =IF(IF('Technology direction'!D5="",'Technology direction'!C5,'Technology direction'!D5)="","",IF('Technology direction'!D5="",'Technology direction'!C5,'Technology direction'!D5)) | Y5: =IF('Technology direction'!H5="","",'Technology direction'!H5) | Z5: =IF('Answers out'!K5="","",'Answers out'!K5) | AA5: =IF('Answers out'!C5="","",'Answers out'!C5) | AB5: =IF('Answers out'!N5="","",'Answers out'!N5)
J6: =IF(Scoring!N6="","",ROUND(Scoring!N6/3,1)) | K6: =IF(Scoring!M6="","",ROUND(Scoring!M6/3,1)) | L6: =IF(Scoring!L6="","",ROUND(Scoring!L6/3,1)) | N6: =IF(COUNT(J6:M6)<4,"",SUM(J6:M6)) | T6: =IF(COUNTBLANK(O6:S6)>0,"",IF(P6="Yes","Predictive or optimisation",IF(O6="No","Automation",IF(AND(Q6="Yes",R6="Yes",S6="Yes"),"Agent",IF(AND(Q6="No",R6="No"),"Retrieval","LLM-augmented workflow"))))) | V6: =IF(U6="","",IF(U6="Automation","Power Automate, Logic Apps or code. No AI governance.",IF(U6="Predictive or optimisation","Fabric data science, Azure ML or a prebuilt Foundry model. Model governance, not agent governance.",IF(U6="Retrieval","SharePoint agent, Copilot Studio retrieval agent or classic RAG. Light governance.",IF(U6="LLM-augmented workflow","A flow with one AI action, or a scheduled prompt. Governance proportional to consequence.","Agent. Continue to Stage 2."))))) | W6: =IF('Assurance and gate'!K6="","",'Assurance and gate'!K6) | X6: =IF(IF('Technology direction'!D6="",'Technology direction'!C6,'Technology direction'!D6)="","",IF('Technology direction'!D6="",'Technology direction'!C6,'Technology direction'!D6)) | Y6: =IF('Technology direction'!H6="","",'Technology direction'!H6) | Z6: =IF('Answers out'!K6="","",'Answers out'!K6) | AA6: =IF('Answers out'!C6="","",'Answers out'!C6) | AB6: =IF('Answers out'!N6="","",'Answers out'!N6)
J7: =IF(Scoring!N7="","",ROUND(Scoring!N7/3,1)) | K7: =IF(Scoring!M7="","",ROUND(Scoring!M7/3,1)) | L7: =IF(Scoring!L7="","",ROUND(Scoring!L7/3,1)) | N7: =IF(COUNT(J7:M7)<4,"",SUM(J7:M7)) | T7: =IF(COUNTBLANK(O7:S7)>0,"",IF(P7="Yes","Predictive or optimisation",IF(O7="No","Automation",IF(AND(Q7="Yes",R7="Yes",S7="Yes"),"Agent",IF(AND(Q7="No",R7="No"),"Retrieval","LLM-augmented workflow"))))) | V7: =IF(U7="","",IF(U7="Automation","Power Automate, Logic Apps or code. No AI governance.",IF(U7="Predictive or optimisation","Fabric data science, Azure ML or a prebuilt Foundry model. Model governance, not agent governance.",IF(U7="Retrieval","SharePoint agent, Copilot Studio retrieval agent or classic RAG. Light governance.",IF(U7="LLM-augmented workflow","A flow with one AI action, or a scheduled prompt. Governance proportional to consequence.","Agent. Continue to Stage 2."))))) | W7: =IF('Assurance and gate'!K7="","",'Assurance and gate'!K7) | X7: =IF(IF('Technology direction'!D7="",'Technology direction'!C7,'Technology direction'!D7)="","",IF('Technology direction'!D7="",'Technology direction'!C7,'Technology direction'!D7)) | Y7: =IF('Technology direction'!H7="","",'Technology direction'!H7) | Z7: =IF('Answers out'!K7="","",'Answers out'!K7) | AA7: =IF('Answers out'!C7="","",'Answers out'!C7) | AB7: =IF('Answers out'!N7="","",'Answers out'!N7)
J8: =IF(Scoring!N8="","",ROUND(Scoring!N8/3,1)) | K8: =IF(Scoring!M8="","",ROUND(Scoring!M8/3,1)) | L8: =IF(Scoring!L8="","",ROUND(Scoring!L8/3,1)) | N8: =IF(COUNT(J8:M8)<4,"",SUM(J8:M8)) | T8: =IF(COUNTBLANK(O8:S8)>0,"",IF(P8="Yes","Predictive or optimisation",IF(O8="No","Automation",IF(AND(Q8="Yes",R8="Yes",S8="Yes"),"Agent",IF(AND(Q8="No",R8="No"),"Retrieval","LLM-augmented workflow"))))) | V8: =IF(U8="","",IF(U8="Automation","Power Automate, Logic Apps or code. No AI governance.",IF(U8="Predictive or optimisation","Fabric data science, Azure ML or a prebuilt Foundry model. Model governance, not agent governance.",IF(U8="Retrieval","SharePoint agent, Copilot Studio retrieval agent or classic RAG. Light governance.",IF(U8="LLM-augmented workflow","A flow with one AI action, or a scheduled prompt. Governance proportional to consequence.","Agent. Continue to Stage 2."))))) | W8: =IF('Assurance and gate'!K8="","",'Assurance and gate'!K8) | X8: =IF(IF('Technology direction'!D8="",'Technology direction'!C8,'Technology direction'!D8)="","",IF('Technology direction'!D8="",'Technology direction'!C8,'Technology direction'!D8)) | Y8: =IF('Technology direction'!H8="","",'Technology direction'!H8) | Z8: =IF('Answers out'!K8="","",'Answers out'!K8) | AA8: =IF('Answers out'!C8="","",'Answers out'!C8) | AB8: =IF('Answers out'!N8="","",'Answers out'!N8)
J9: =IF(Scoring!N9="","",ROUND(Scoring!N9/3,1)) | K9: =IF(Scoring!M9="","",ROUND(Scoring!M9/3,1)) | L9: =IF(Scoring!L9="","",ROUND(Scoring!L9/3,1)) | N9: =IF(COUNT(J9:M9)<4,"",SUM(J9:M9)) | T9: =IF(COUNTBLANK(O9:S9)>0,"",IF(P9="Yes","Predictive or optimisation",IF(O9="No","Automation",IF(AND(Q9="Yes",R9="Yes",S9="Yes"),"Agent",IF(AND(Q9="No",R9="No"),"Retrieval","LLM-augmented workflow"))))) | V9: =IF(U9="","",IF(U9="Automation","Power Automate, Logic Apps or code. No AI governance.",IF(U9="Predictive or optimisation","Fabric data science, Azure ML or a prebuilt Foundry model. Model governance, not agent governance.",IF(U9="Retrieval","SharePoint agent, Copilot Studio retrieval agent or classic RAG. Light governance.",IF(U9="LLM-augmented workflow","A flow with one AI action, or a scheduled prompt. Governance proportional to consequence.","Agent. Continue to Stage 2."))))) | W9: =IF('Assurance and gate'!K9="","",'Assurance and gate'!K9) | X9: =IF(IF('Technology direction'!D9="",'Technology direction'!C9,'Technology direction'!D9)="","",IF('Technology direction'!D9="",'Technology direction'!C9,'Technology direction'!D9)) | Y9: =IF('Technology direction'!H9="","",'Technology direction'!H9) | Z9: =IF('Answers out'!K9="","",'Answers out'!K9) | AA9: =IF('Answers out'!C9="","",'Answers out'!C9) | AB9: =IF('Answers out'!N9="","",'Answers out'!N9)
J10: =IF(Scoring!N10="","",ROUND(Scoring!N10/3,1)) | K10: =IF(Scoring!M10="","",ROUND(Scoring!M10/3,1)) | L10: =IF(Scoring!L10="","",ROUND(Scoring!L10/3,1)) | N10: =IF(COUNT(J10:M10)<4,"",SUM(J10:M10)) | T10: =IF(COUNTBLANK(O10:S10)>0,"",IF(P10="Yes","Predictive or optimisation",IF(O10="No","Automation",IF(AND(Q10="Yes",R10="Yes",S10="Yes"),"Agent",IF(AND(Q10="No",R10="No"),"Retrieval","LLM-augmented workflow"))))) | V10: =IF(U10="","",IF(U10="Automation","Power Automate, Logic Apps or code. No AI governance.",IF(U10="Predictive or optimisation","Fabric data science, Azure ML or a prebuilt Foundry model. Model governance, not agent governance.",IF(U10="Retrieval","SharePoint agent, Copilot Studio retrieval agent or classic RAG. Light governance.",IF(U10="LLM-augmented workflow","A flow with one AI action, or a scheduled prompt. Governance proportional to consequence.","Agent. Continue to Stage 2."))))) | W10: =IF('Assurance and gate'!K10="","",'Assurance and gate'!K10) | X10: =IF(IF('Technology direction'!D10="",'Technology direction'!C10,'Technology direction'!D10)="","",IF('Technology direction'!D10="",'Technology direction'!C10,'Technology direction'!D10)) | Y10: =IF('Technology direction'!H10="","",'Technology direction'!H10) | Z10: =IF('Answers out'!K10="","",'Answers out'!K10) | AA10: =IF('Answers out'!C10="","",'Answers out'!C10) | AB10: =IF('Answers out'!N10="","",'Answers out'!N10)
J11: =IF(Scoring!N11="","",ROUND(Scoring!N11/3,1)) | K11: =IF(Scoring!M11="","",ROUND(Scoring!M11/3,1)) | L11: =IF(Scoring!L11="","",ROUND(Scoring!L11/3,1)) | N11: =IF(COUNT(J11:M11)<4,"",SUM(J11:M11)) | T11: =IF(COUNTBLANK(O11:S11)>0,"",IF(P11="Yes","Predictive or optimisation",IF(O11="No","Automation",IF(AND(Q11="Yes",R11="Yes",S11="Yes"),"Agent",IF(AND(Q11="No",R11="No"),"Retrieval","LLM-augmented workflow"))))) | V11: =IF(U11="","",IF(U11="Automation","Power Automate, Logic Apps or code. No AI governance.",IF(U11="Predictive or optimisation","Fabric data science, Azure ML or a prebuilt Foundry model. Model governance, not agent governance.",IF(U11="Retrieval","SharePoint agent, Copilot Studio retrieval agent or classic RAG. Light governance.",IF(U11="LLM-augmented workflow","A flow with one AI action, or a scheduled prompt. Governance proportional to consequence.","Agent. Continue to Stage 2."))))) | W11: =IF('Assurance and gate'!K11="","",'Assurance and gate'!K11) | X11: =IF(IF('Technology direction'!D11="",'Technology direction'!C11,'Technology direction'!D11)="","",IF('Technology direction'!D11="",'Technology direction'!C11,'Technology direction'!D11)) | Y11: =IF('Technology direction'!H11="","",'Technology direction'!H11) | Z11: =IF('Answers out'!K11="","",'Answers out'!K11) | AA11: =IF('Answers out'!C11="","",'Answers out'!C11) | AB11: =IF('Answers out'!N11="","",'Answers out'!N11)
J12: =IF(Scoring!N12="","",ROUND(Scoring!N12/3,1)) | K12: =IF(Scoring!M12="","",ROUND(Scoring!M12/3,1)) | L12: =IF(Scoring!L12="","",ROUND(Scoring!L12/3,1)) | N12: =IF(COUNT(J12:M12)<4,"",SUM(J12:M12)) | T12: =IF(COUNTBLANK(O12:S12)>0,"",IF(P12="Yes","Predictive or optimisation",IF(O12="No","Automation",IF(AND(Q12="Yes",R12="Yes",S12="Yes"),"Agent",IF(AND(Q12="No",R12="No"),"Retrieval","LLM-augmented workflow"))))) | V12: =IF(U12="","",IF(U12="Automation","Power Automate, Logic Apps or code. No AI governance.",IF(U12="Predictive or optimisation","Fabric data science, Azure ML or a prebuilt Foundry model. Model governance, not agent governance.",IF(U12="Retrieval","SharePoint agent, Copilot Studio retrieval agent or classic RAG. Light governance.",IF(U12="LLM-augmented workflow","A flow with one AI action, or a scheduled prompt. Governance proportional to consequence.","Agent. Continue to Stage 2."))))) | W12: =IF('Assurance and gate'!K12="","",'Assurance and gate'!K12) | X12: =IF(IF('Technology direction'!D12="",'Technology direction'!C12,'Technology direction'!D12)="","",IF('Technology direction'!D12="",'Technology direction'!C12,'Technology direction'!D12)) | Y12: =IF('Technology direction'!H12="","",'Technology direction'!H12) | Z12: =IF('Answers out'!K12="","",'Answers out'!K12) | AA12: =IF('Answers out'!C12="","",'Answers out'!C12) | AB12: =IF('Answers out'!N12="","",'Answers out'!N12)
J13: =IF(Scoring!N13="","",ROUND(Scoring!N13/3,1)) | K13: =IF(Scoring!M13="","",ROUND(Scoring!M13/3,1)) | L13: =IF(Scoring!L13="","",ROUND(Scoring!L13/3,1)) | N13: =IF(COUNT(J13:M13)<4,"",SUM(J13:M13)) | T13: =IF(COUNTBLANK(O13:S13)>0,"",IF(P13="Yes","Predictive or optimisation",IF(O13="No","Automation",IF(AND(Q13="Yes",R13="Yes",S13="Yes"),"Agent",IF(AND(Q13="No",R13="No"),"Retrieval","LLM-augmented workflow"))))) | V13: =IF(U13="","",IF(U13="Automation","Power Automate, Logic Apps or code. No AI governance.",IF(U13="Predictive or optimisation","Fabric data science, Azure ML or a prebuilt Foundry model. Model governance, not agent governance.",IF(U13="Retrieval","SharePoint agent, Copilot Studio retrieval agent or classic RAG. Light governance.",IF(U13="LLM-augmented workflow","A flow with one AI action, or a scheduled prompt. Governance proportional to consequence.","Agent. Continue to Stage 2."))))) | W13: =IF('Assurance and gate'!K13="","",'Assurance and gate'!K13) | X13: =IF(IF('Technology direction'!D13="",'Technology direction'!C13,'Technology direction'!D13)="","",IF('Technology direction'!D13="",'Technology direction'!C13,'Technology direction'!D13)) | Y13: =IF('Technology direction'!H13="","",'Technology direction'!H13) | Z13: =IF('Answers out'!K13="","",'Answers out'!K13) | AA13: =IF('Answers out'!C13="","",'Answers out'!C13) | AB13: =IF('Answers out'!N13="","",'Answers out'!N13)
J14: =IF(Scoring!N14="","",ROUND(Scoring!N14/3,1)) | K14: =IF(Scoring!M14="","",ROUND(Scoring!M14/3,1)) | L14: =IF(Scoring!L14="","",ROUND(Scoring!L14/3,1)) | N14: =IF(COUNT(J14:M14)<4,"",SUM(J14:M14)) | T14: =IF(COUNTBLANK(O14:S14)>0,"",IF(P14="Yes","Predictive or optimisation",IF(O14="No","Automation",IF(AND(Q14="Yes",R14="Yes",S14="Yes"),"Agent",IF(AND(Q14="No",R14="No"),"Retrieval","LLM-augmented workflow"))))) | V14: =IF(U14="","",IF(U14="Automation","Power Automate, Logic Apps or code. No AI governance.",IF(U14="Predictive or optimisation","Fabric data science, Azure ML or a prebuilt Foundry model. Model governance, not agent governance.",IF(U14="Retrieval","SharePoint agent, Copilot Studio retrieval agent or classic RAG. Light governance.",IF(U14="LLM-augmented workflow","A flow with one AI action, or a scheduled prompt. Governance proportional to consequence.","Agent. Continue to Stage 2."))))) | W14: =IF('Assurance and gate'!K14="","",'Assurance and gate'!K14) | X14: =IF(IF('Technology direction'!D14="",'Technology direction'!C14,'Technology direction'!D14)="","",IF('Technology direction'!D14="",'Technology direction'!C14,'Technology direction'!D14)) | Y14: =IF('Technology direction'!H14="","",'Technology direction'!H14) | Z14: =IF('Answers out'!K14="","",'Answers out'!K14) | AA14: =IF('Answers out'!C14="","",'Answers out'!C14) | AB14: =IF('Answers out'!N14="","",'Answers out'!N14)
J15: =IF(Scoring!N15="","",ROUND(Scoring!N15/3,1)) | K15: =IF(Scoring!M15="","",ROUND(Scoring!M15/3,1)) | L15: =IF(Scoring!L15="","",ROUND(Scoring!L15/3,1)) | N15: =IF(COUNT(J15:M15)<4,"",SUM(J15:M15)) | T15: =IF(COUNTBLANK(O15:S15)>0,"",IF(P15="Yes","Predictive or optimisation",IF(O15="No","Automation",IF(AND(Q15="Yes",R15="Yes",S15="Yes"),"Agent",IF(AND(Q15="No",R15="No"),"Retrieval","LLM-augmented workflow"))))) | V15: =IF(U15="","",IF(U15="Automation","Power Automate, Logic Apps or code. No AI governance.",IF(U15="Predictive or optimisation","Fabric data science, Azure ML or a prebuilt Foundry model. Model governance, not agent governance.",IF(U15="Retrieval","SharePoint agent, Copilot Studio retrieval agent or classic RAG. Light governance.",IF(U15="LLM-augmented workflow","A flow with one AI action, or a scheduled prompt. Governance proportional to consequence.","Agent. Continue to Stage 2."))))) | W15: =IF('Assurance and gate'!K15="","",'Assurance and gate'!K15) | X15: =IF(IF('Technology direction'!D15="",'Technology direction'!C15,'Technology direction'!D15)="","",IF('Technology direction'!D15="",'Technology direction'!C15,'Technology direction'!D15)) | Y15: =IF('Technology direction'!H15="","",'Technology direction'!H15) | Z15: =IF('Answers out'!K15="","",'Answers out'!K15) | AA15: =IF('Answers out'!C15="","",'Answers out'!C15) | AB15: =IF('Answers out'!N15="","",'Answers out'!N15)
J16: =IF(Scoring!N16="","",ROUND(Scoring!N16/3,1)) | K16: =IF(Scoring!M16="","",ROUND(Scoring!M16/3,1)) | L16: =IF(Scoring!L16="","",ROUND(Scoring!L16/3,1)) | N16: =IF(COUNT(J16:M16)<4,"",SUM(J16:M16)) | T16: =IF(COUNTBLANK(O16:S16)>0,"",IF(P16="Yes","Predictive or optimisation",IF(O16="No","Automation",IF(AND(Q16="Yes",R16="Yes",S16="Yes"),"Agent",IF(AND(Q16="No",R16="No"),"Retrieval","LLM-augmented workflow"))))) | V16: =IF(U16="","",IF(U16="Automation","Power Automate, Logic Apps or code. No AI governance.",IF(U16="Predictive or optimisation","Fabric data science, Azure ML or a prebuilt Foundry model. Model governance, not agent governance.",IF(U16="Retrieval","SharePoint agent, Copilot Studio retrieval agent or classic RAG. Light governance.",IF(U16="LLM-augmented workflow","A flow with one AI action, or a scheduled prompt. Governance proportional to consequence.","Agent. Continue to Stage 2."))))) | W16: =IF('Assurance and gate'!K16="","",'Assurance and gate'!K16) | X16: =IF(IF('Technology direction'!D16="",'Technology direction'!C16,'Technology direction'!D16)="","",IF('Technology direction'!D16="",'Technology direction'!C16,'Technology direction'!D16)) | Y16: =IF('Technology direction'!H16="","",'Technology direction'!H16) | Z16: =IF('Answers out'!K16="","",'Answers out'!K16) | AA16: =IF('Answers out'!C16="","",'Answers out'!C16) | AB16: =IF('Answers out'!N16="","",'Answers out'!N16)
... J52: =IF(Scoring!N52="","",ROUND(Scoring!N52/3,1)) | K52: =IF(Scoring!M52="","",ROUND(Scoring!M52/3,1)) | L52: =IF(Scoring!L52="","",ROUND(Scoring!L52/3,1)) | N52: =IF(COUNT(J52:M52)<4,"",SUM(J52:M52)) | T52: =IF(COUNTBLANK(O52:S52)>0,"",IF(P52="Yes","Predictive or optimisation",IF(O52="No","Automation",IF(AND(Q52="Yes",R52="Yes",S52="Yes"),"Agent",IF(AND(Q52="No",R52="No"),"Retrieval","LLM-augmented workflow"))))) | V52: =IF(U52="","",IF(U52="Automation","Power Automate, Logic Apps or code. No AI governance.",IF(U52="Predictive or optimisation","Fabric data science, Azure ML or a prebuilt Foundry model. Model governance, not agent governance.",IF(U52="Retrieval","SharePoint agent, Copilot Studio retrieval agent or classic RAG. Light governance.",IF(U52="LLM-augmented workflow","A flow with one AI action, or a scheduled prompt. Governance proportional to consequence.","Agent. Continue to Stage 2."))))) | W52: =IF('Assurance and gate'!K52="","",'Assurance and gate'!K52) | X52: =IF(IF('Technology direction'!D52="",'Technology direction'!C52,'Technology direction'!D52)="","",IF('Technology direction'!D52="",'Technology direction'!C52,'Technology direction'!D52)) | Y52: =IF('Technology direction'!H52="","",'Technology direction'!H52) | Z52: =IF('Answers out'!K52="","",'Answers out'!K52) | AA52: =IF('Answers out'!C52="","",'Answers out'!C52) | AB52: =IF('Answers out'!N52="","",'Answers out'!N52)

Sheet Outcome contract
A1: USE CASE | C1: THE CONTRACT - five things, all before anyone opens a product page | M1: 5 THE VALUE BASELINE - six measurements of the process as it runs today | V1: CALCULATED
A2: ID | B2: Use case | C2: 1 The result: an outcome with a number, not a feature | D2: Metric that moves | E2: Baseline today | F2: Target | G2: 2 Owner: build | H2: 2 Owner: after go-live | I2: 3 The boundary: what it will explicitly refuse to do | J2: 4 Gate: prototype | K2: 4 Gate: pilot | L2: 4 Gate: release | M2: V1 People doing this work today | N2: V2 Times per person per year | O2: V3 Minutes each time | P2: V4a How often it goes wrong | Q2: V4b Cost each time it goes wrong | R2: V5 Metric today | S2: V6 What happens to the time saved | T2: Benefit type | U2: Hard or soft | V2: Annual hours in the process today | W2: Annual cost of getting it wrong | X2: Value baseline captured | Y2: Note
A3: =IF(Register!A3="","",Register!A3) | B3: =IF(Register!C3="","",Register!C3) | C3: Cut policy questions reaching the P&C inbox from 240 a month to under 100, within one quarter of release. | D3: Policy questions reaching the P&C shared inbox each month | E3: 240 a month | F3: Under 100 a month | G3: A. Whitfield | H3: D. Okonjo, P&C Systems Lead | I3: Will not interpret an individual employment contract, will not comment on a live grievance, and will not answer anything the policy library does not cover. Says so and names the person to ask. | J3: Answers 20 seeded questions with the correct source document cited. | K3: 30 staff over 4 weeks. At least 70 per cent rate the answer useful, and no incorrect citation. | L3: Inbox volume down 30 per cent, and the monthly spot check clean two months running. | M3: 480 | N3: 6 | O3: 12 | P3: 0.08 | Q3: 35 | R3: =IF(E3="","",E3) | S3: Returned to P&C advisers as casework time. Two advisers move off inbox triage onto the case backlog, which is the constraint the team actually feels. | T3: Time or cost released | U3: Hard | V3: =IF(COUNT(M3:O3)<3,"",M3*N3*O3/60) | W3: =IF(COUNT(M3,N3,P3,Q3)<4,"",M3*N3*P3*Q3) | X3: =IF(B3="","",(6-COUNTBLANK(M3)-COUNTBLANK(N3)-COUNTBLANK(O3)-COUNTBLANK(P3)-COUNTBLANK(Q3)-COUNTBLANK(S3))/6)
A4: =IF(Register!A4="","",Register!A4) | B4: =IF(Register!C4="","",Register!C4) | C4: Cut after-hours documentation from 45 minutes a shift to under 15, without the clinical note audit score falling. | D4: Documentation minutes per care worker per shift, and the monthly clinical note audit score | E4: 45 minutes a shift. Audit score 82 per cent. | F4: Under 15 minutes, with the audit score no lower than 82 per cent | G4: Dr M. Ferreira | I4: Will not make a clinical assessment, will not change a care plan, will not record a medication administration, and will not file any note the care worker has not confirmed on screen. | J4: Transcribes 30 recorded visits with no clinical terminology errors in a clinician review. | K4: 12 care workers, 4 weeks, across two regions including one with poor mobile coverage. Notes audited weekly. | L4: Audit score held, consent position signed off by Privacy, and zero notes filed without confirmation. | M4: 620 | N4: 210 | O4: 45 | P4: 0.12 | Q4: 60 | R4: =IF(E4="","",E4) | S4: Returned to direct client contact. Measured against the board target of two extra client-facing hours per care worker per fortnight, not against headcount. | T4: Capacity redirected to the mission | U4: Soft | V4: =IF(COUNT(M4:O4)<3,"",M4*N4*O4/60) | W4: =IF(COUNT(M4,N4,P4,Q4)<4,"",M4*N4*P4*Q4) | X4: =IF(B4="","",(6-COUNTBLANK(M4)-COUNTBLANK(N4)-COUNTBLANK(O4)-COUNTBLANK(P4)-COUNTBLANK(Q4)-COUNTBLANK(S4))/6)
A5: =IF(Register!A5="","",Register!A5) | B5: =IF(Register!C5="","",Register!C5) | R5: =IF(E5="","",E5) | V5: =IF(COUNT(M5:O5)<3,"",M5*N5*O5/60) | W5: =IF(COUNT(M5,N5,P5,Q5)<4,"",M5*N5*P5*Q5) | X5: =IF(B5="","",(6-COUNTBLANK(M5)-COUNTBLANK(N5)-COUNTBLANK(O5)-COUNTBLANK(P5)-COUNTBLANK(Q5)-COUNTBLANK(S5))/6)
A6: =IF(Register!A6="","",Register!A6) | B6: =IF(Register!C6="","",Register!C6) | R6: =IF(E6="","",E6) | V6: =IF(COUNT(M6:O6)<3,"",M6*N6*O6/60) | W6: =IF(COUNT(M6,N6,P6,Q6)<4,"",M6*N6*P6*Q6) | X6: =IF(B6="","",(6-COUNTBLANK(M6)-COUNTBLANK(N6)-COUNTBLANK(O6)-COUNTBLANK(P6)-COUNTBLANK(Q6)-COUNTBLANK(S6))/6)
A7: =IF(Register!A7="","",Register!A7) | B7: =IF(Register!C7="","",Register!C7) | R7: =IF(E7="","",E7) | V7: =IF(COUNT(M7:O7)<3,"",M7*N7*O7/60) | W7: =IF(COUNT(M7,N7,P7,Q7)<4,"",M7*N7*P7*Q7) | X7: =IF(B7="","",(6-COUNTBLANK(M7)-COUNTBLANK(N7)-COUNTBLANK(O7)-COUNTBLANK(P7)-COUNTBLANK(Q7)-COUNTBLANK(S7))/6)
A8: =IF(Register!A8="","",Register!A8) | B8: =IF(Register!C8="","",Register!C8) | R8: =IF(E8="","",E8) | V8: =IF(COUNT(M8:O8)<3,"",M8*N8*O8/60) | W8: =IF(COUNT(M8,N8,P8,Q8)<4,"",M8*N8*P8*Q8) | X8: =IF(B8="","",(6-COUNTBLANK(M8)-COUNTBLANK(N8)-COUNTBLANK(O8)-COUNTBLANK(P8)-COUNTBLANK(Q8)-COUNTBLANK(S8))/6)
A9: =IF(Register!A9="","",Register!A9) | B9: =IF(Register!C9="","",Register!C9) | R9: =IF(E9="","",E9) | V9: =IF(COUNT(M9:O9)<3,"",M9*N9*O9/60) | W9: =IF(COUNT(M9,N9,P9,Q9)<4,"",M9*N9*P9*Q9) | X9: =IF(B9="","",(6-COUNTBLANK(M9)-COUNTBLANK(N9)-COUNTBLANK(O9)-COUNTBLANK(P9)-COUNTBLANK(Q9)-COUNTBLANK(S9))/6)
A10: =IF(Register!A10="","",Register!A10) | B10: =IF(Register!C10="","",Register!C10) | R10: =IF(E10="","",E10) | V10: =IF(COUNT(M10:O10)<3,"",M10*N10*O10/60) | W10: =IF(COUNT(M10,N10,P10,Q10)<4,"",M10*N10*P10*Q10) | X10: =IF(B10="","",(6-COUNTBLANK(M10)-COUNTBLANK(N10)-COUNTBLANK(O10)-COUNTBLANK(P10)-COUNTBLANK(Q10)-COUNTBLANK(S10))/6)
A11: =IF(Register!A11="","",Register!A11) | B11: =IF(Register!C11="","",Register!C11) | R11: =IF(E11="","",E11) | V11: =IF(COUNT(M11:O11)<3,"",M11*N11*O11/60) | W11: =IF(COUNT(M11,N11,P11,Q11)<4,"",M11*N11*P11*Q11) | X11: =IF(B11="","",(6-COUNTBLANK(M11)-COUNTBLANK(N11)-COUNTBLANK(O11)-COUNTBLANK(P11)-COUNTBLANK(Q11)-COUNTBLANK(S11))/6)
A12: =IF(Register!A12="","",Register!A12) | B12: =IF(Register!C12="","",Register!C12) | R12: =IF(E12="","",E12) | V12: =IF(COUNT(M12:O12)<3,"",M12*N12*O12/60) | W12: =IF(COUNT(M12,N12,P12,Q12)<4,"",M12*N12*P12*Q12) | X12: =IF(B12="","",(6-COUNTBLANK(M12)-COUNTBLANK(N12)-COUNTBLANK(O12)-COUNTBLANK(P12)-COUNTBLANK(Q12)-COUNTBLANK(S12))/6)
A13: =IF(Register!A13="","",Register!A13) | B13: =IF(Register!C13="","",Register!C13) | R13: =IF(E13="","",E13) | V13: =IF(COUNT(M13:O13)<3,"",M13*N13*O13/60) | W13: =IF(COUNT(M13,N13,P13,Q13)<4,"",M13*N13*P13*Q13) | X13: =IF(B13="","",(6-COUNTBLANK(M13)-COUNTBLANK(N13)-COUNTBLANK(O13)-COUNTBLANK(P13)-COUNTBLANK(Q13)-COUNTBLANK(S13))/6)
A14: =IF(Register!A14="","",Register!A14) | B14: =IF(Register!C14="","",Register!C14) | R14: =IF(E14="","",E14) | V14: =IF(COUNT(M14:O14)<3,"",M14*N14*O14/60) | W14: =IF(COUNT(M14,N14,P14,Q14)<4,"",M14*N14*P14*Q14) | X14: =IF(B14="","",(6-COUNTBLANK(M14)-COUNTBLANK(N14)-COUNTBLANK(O14)-COUNTBLANK(P14)-COUNTBLANK(Q14)-COUNTBLANK(S14))/6)
A15: =IF(Register!A15="","",Register!A15) | B15: =IF(Register!C15="","",Register!C15) | R15: =IF(E15="","",E15) | V15: =IF(COUNT(M15:O15)<3,"",M15*N15*O15/60) | W15: =IF(COUNT(M15,N15,P15,Q15)<4,"",M15*N15*P15*Q15) | X15: =IF(B15="","",(6-COUNTBLANK(M15)-COUNTBLANK(N15)-COUNTBLANK(O15)-COUNTBLANK(P15)-COUNTBLANK(Q15)-COUNTBLANK(S15))/6)
A16: =IF(Register!A16="","",Register!A16) | B16: =IF(Register!C16="","",Register!C16) | R16: =IF(E16="","",E16) | V16: =IF(COUNT(M16:O16)<3,"",M16*N16*O16/60) | W16: =IF(COUNT(M16,N16,P16,Q16)<4,"",M16*N16*P16*Q16) | X16: =IF(B16="","",(6-COUNTBLANK(M16)-COUNTBLANK(N16)-COUNTBLANK(O16)-COUNTBLANK(P16)-COUNTBLANK(Q16)-COUNTBLANK(S16))/6)
... A52: =IF(Register!A52="","",Register!A52) | B52: =IF(Register!C52="","",Register!C52) | R52: =IF(E52="","",E52) | V52: =IF(COUNT(M52:O52)<3,"",M52*N52*O52/60) | W52: =IF(COUNT(M52,N52,P52,Q52)<4,"",M52*N52*P52*Q52) | X52: =IF(B52="","",(6-COUNTBLANK(M52)-COUNTBLANK(N52)-COUNTBLANK(O52)-COUNTBLANK(P52)-COUNTBLANK(Q52)-COUNTBLANK(S52))/6)

Sheet Eight questions
A1: USE CASE | C1: Q1-Q4 SHAPE, REACH AND IDENTITY | J1: Q5-Q8 DATA, CONNECTION AND CONSEQUENCE | Q1: RECORDED, BUT NOT QUESTIONS
A2: ID | B2: Use case | C2: Q1 What starts it? | D2: Q2 Where does the answer land? | E2: Q2b Connectivity assumption | F2: Q3 Intended reach | G2: Q3 Pilot reach | H2: Q4 Whose permissions? | I2: Q4 Identity of record | J2: Q5 What class of data? | K2: Q5 What that forces | L2: Q6 What must it know or do? | M2: Q7 Does the connection exist? | N2: Q7 Source systems | O2: Q8a If it gives a wrong answer | P2: Q8b If it silently does nothing | Q2: Ready-made agent available? | R2: Do these users have the licences? | S2: Needs memory between uses? | T2: Will it grow beyond 3-5 functions? | U2: How often the source changes | V2: Retrieval decision record
A3: =IF(Register!A3="","",Register!A3) | B3: =IF(Register!C3="","",Register!C3) | C3: A person asks | D3: Collaboration surface | E3: Always connected | F3: 2 My team | G3: 2 My team | H3: Acts as the user | I3: Entra Agent ID agent-policy-assistant-prod | J3: Internal | K3: =IF(J3="","",INDEX(Lists!$B$53:$B$56,MATCH(J3,Lists!$A$53:$A$56,0))) | L3: Static documents | M3: Yes, in production | N3: SharePoint Online, Policy Library site. No other source. | O3: Read only | P3: Nothing | Q3: Yes | R3: Yes | S3: No | T3: No | U3: Policies are reviewed annually. Roughly six documents change a quarter. | V3: Policy documents: retrieval over the governed SharePoint index, inheriting the document permissions that already exist. No tool calls and no write scope, so there is nothing else to record.
A4: =IF(Register!A4="","",Register!A4) | B4: =IF(Register!C4="","",Register!C4) | C4: A person is already working | D4: Frontline device | E4: Must work offline | F4: 4 Enterprise | G4: 2 My team | H4: Acts as the user | I4: Entra Agent ID agent-clinical-scribe-nonprod. The production identity has not been issued. | J4: Regulated | K4: =IF(J4="","",INDEX(Lists!$B$53:$B$56,MATCH(J4,Lists!$A$53:$A$56,0))) | L4: Take an action | M4: No | N4: AlayaCare client record system, and the mobile visit app. There is no write API to AlayaCare today. | O4: Writes to a system | P4: A person is affected | Q4: No | R4: No | S4: No | T4: Yes | U4: The client record changes continuously through the day. | V4: Clinical notes: MCP call to AlayaCare, write scope, care worker confirmation required before the write. No index of clinical content is created. Terminology list: retrieval over a governed index.
A5: =IF(Register!A5="","",Register!A5) | B5: =IF(Register!C5="","",Register!C5) | K5: =IF(J5="","",INDEX(Lists!$B$53:$B$56,MATCH(J5,Lists!$A$53:$A$56,0)))
A6: =IF(Register!A6="","",Register!A6) | B6: =IF(Register!C6="","",Register!C6) | K6: =IF(J6="","",INDEX(Lists!$B$53:$B$56,MATCH(J6,Lists!$A$53:$A$56,0)))
A7: =IF(Register!A7="","",Register!A7) | B7: =IF(Register!C7="","",Register!C7) | K7: =IF(J7="","",INDEX(Lists!$B$53:$B$56,MATCH(J7,Lists!$A$53:$A$56,0)))
A8: =IF(Register!A8="","",Register!A8) | B8: =IF(Register!C8="","",Register!C8) | K8: =IF(J8="","",INDEX(Lists!$B$53:$B$56,MATCH(J8,Lists!$A$53:$A$56,0)))
A9: =IF(Register!A9="","",Register!A9) | B9: =IF(Register!C9="","",Register!C9) | K9: =IF(J9="","",INDEX(Lists!$B$53:$B$56,MATCH(J9,Lists!$A$53:$A$56,0)))
A10: =IF(Register!A10="","",Register!A10) | B10: =IF(Register!C10="","",Register!C10) | K10: =IF(J10="","",INDEX(Lists!$B$53:$B$56,MATCH(J10,Lists!$A$53:$A$56,0)))
A11: =IF(Register!A11="","",Register!A11) | B11: =IF(Register!C11="","",Register!C11) | K11: =IF(J11="","",INDEX(Lists!$B$53:$B$56,MATCH(J11,Lists!$A$53:$A$56,0)))
A12: =IF(Register!A12="","",Register!A12) | B12: =IF(Register!C12="","",Register!C12) | K12: =IF(J12="","",INDEX(Lists!$B$53:$B$56,MATCH(J12,Lists!$A$53:$A$56,0)))
A13: =IF(Register!A13="","",Register!A13) | B13: =IF(Register!C13="","",Register!C13) | K13: =IF(J13="","",INDEX(Lists!$B$53:$B$56,MATCH(J13,Lists!$A$53:$A$56,0)))
A14: =IF(Register!A14="","",Register!A14) | B14: =IF(Register!C14="","",Register!C14) | K14: =IF(J14="","",INDEX(Lists!$B$53:$B$56,MATCH(J14,Lists!$A$53:$A$56,0)))
A15: =IF(Register!A15="","",Register!A15) | B15: =IF(Register!C15="","",Register!C15) | K15: =IF(J15="","",INDEX(Lists!$B$53:$B$56,MATCH(J15,Lists!$A$53:$A$56,0)))
A16: =IF(Register!A16="","",Register!A16) | B16: =IF(Register!C16="","",Register!C16) | K16: =IF(J16="","",INDEX(Lists!$B$53:$B$56,MATCH(J16,Lists!$A$53:$A$56,0)))
... A52: =IF(Register!A52="","",Register!A52) | B52: =IF(Register!C52="","",Register!C52) | K52: =IF(J52="","",INDEX(Lists!$B$53:$B$56,MATCH(J52,Lists!$A$53:$A$56,0)))

Sheet Assurance and gate
A1: USE CASE | C1: THE TIER, WITH THE WORKING SHOWN | P1: RELEASE GATE - no agent moves forward without passing | X1: CONTROL PLANE BASELINE - applies at every tier, including tier 1
A2: ID | B2: Use case | C2: Q8a consequence | D2: Q3 intended reach | E2: Reach band | F2: Base tier from the matrix | G2: Q8b lift | H2: Q5 floor | I2: Base ordinal | J2: Final ordinal | K2: ASSURANCE TIER | L2: What that means | M2: Named approver | N2: Human in the loop: the trigger condition | O2: Has reject ever been exercised? | P2: 1 Accountable | Q2: 2 Identifiable | R2: 3 Constrained | S2: 4 Tested | T2: 5 Observable | U2: 6 Recoverable | V2: Evidence / link | W2: GATE STATUS | X2: Registry entry | Y2: Cost tag | Z2: Observability | AA2: AI involvement disclosed | AB2: What happens when the owner leaves
A3: =IF(Register!A3="","",Register!A3) | B3: =IF(Register!C3="","",Register!C3) | C3: =IF('Eight questions'!O3="","",'Eight questions'!O3) | D3: =IF('Eight questions'!F3="","",'Eight questions'!F3) | E3: =IF(D3="","",IF(VALUE(LEFT(D3,1))<=2,"1-2",IF(VALUE(LEFT(D3,1))=3,"3","4-5"))) | F3: =IF(OR(C3="",E3=""),"",INDEX(Lists!$B$32:$D$34,MATCH(C3,Lists!$A$32:$A$34,0),MATCH(E3,Lists!$B$31:$D$31,0))) | G3: =IF(F3="","",IF('Eight questions'!P3="A person is affected",1,0)) | H3: =IF(F3="","",IF('Eight questions'!J3="Regulated",3,1)) | I3: =IF(F3="","",MATCH(F3,Lists!$A$37:$A$40,0)) | J3: =IF(I3="","",MIN(4,MAX(I3+G3,H3))) | K3: =IF(J3="","",INDEX(Lists!$A$37:$A$40,J3)) | L3: =IF(J3="","",INDEX(Lists!$C$37:$C$40,J3)) | M3: A. Whitfield | N3: Ten answers a month are spot checked against the source document. Any answer citing a superseded policy goes straight to the P&C Systems Lead. | O3: Yes | P3: Met | Q3: Met | R3: Met | S3: Met | T3: Met | U3: Met | V3: Governance register entry GOV-2026-114 | W3: =IF(COUNTA(P3:U3)=0,"",IF(COUNTIF(P3:U3,"Not met")>0,"Blocked",IF(COUNTIF(P3:U3,"In progress")>0,"In progress",IF(COUNTA(P3:U3)<6,"Incomplete","Passed")))) | X3: Yes | Y3: Yes | Z3: Yes | AA3: Yes | AB3: Ownership sits with the P&C Operations Manager role, not the individual. Recorded on the registry entry.
A4: =IF(Register!A4="","",Register!A4) | B4: =IF(Register!C4="","",Register!C4) | C4: =IF('Eight questions'!O4="","",'Eight questions'!O4) | D4: =IF('Eight questions'!F4="","",'Eight questions'!F4) | E4: =IF(D4="","",IF(VALUE(LEFT(D4,1))<=2,"1-2",IF(VALUE(LEFT(D4,1))=3,"3","4-5"))) | F4: =IF(OR(C4="",E4=""),"",INDEX(Lists!$B$32:$D$34,MATCH(C4,Lists!$A$32:$A$34,0),MATCH(E4,Lists!$B$31:$D$31,0))) | G4: =IF(F4="","",IF('Eight questions'!P4="A person is affected",1,0)) | H4: =IF(F4="","",IF('Eight questions'!J4="Regulated",3,1)) | I4: =IF(F4="","",MATCH(F4,Lists!$A$37:$A$40,0)) | J4: =IF(I4="","",MIN(4,MAX(I4+G4,H4))) | K4: =IF(J4="","",INDEX(Lists!$A$37:$A$40,J4)) | L4: =IF(J4="","",INDEX(Lists!$C$37:$C$40,J4)) | M4: Clinical Governance Committee, chaired by Dr M. Ferreira | N4: Every note is confirmed on screen by the care worker before it is filed. Any note the agent flags as uncertain, and every note for a client on a restrictive practice plan, is queued for a clinician first. | O4: No | P4: Met | Q4: In progress | R4: In progress | S4: Not met | T4: Not met | U4: In progress | V4: Draft charter CG-2026-31. The privacy impact assessment has not started. | W4: =IF(COUNTA(P4:U4)=0,"",IF(COUNTIF(P4:U4,"Not met")>0,"Blocked",IF(COUNTIF(P4:U4,"In progress")>0,"In progress",IF(COUNTA(P4:U4)<6,"Incomplete","Passed")))) | X4: No | Y4: Yes | Z4: No | AA4: Yes | AB4: Not answered. On the agenda for the September clinical governance meeting.
A5: =IF(Register!A5="","",Register!A5) | B5: =IF(Register!C5="","",Register!C5) | C5: =IF('Eight questions'!O5="","",'Eight questions'!O5) | D5: =IF('Eight questions'!F5="","",'Eight questions'!F5) | E5: =IF(D5="","",IF(VALUE(LEFT(D5,1))<=2,"1-2",IF(VALUE(LEFT(D5,1))=3,"3","4-5"))) | F5: =IF(OR(C5="",E5=""),"",INDEX(Lists!$B$32:$D$34,MATCH(C5,Lists!$A$32:$A$34,0),MATCH(E5,Lists!$B$31:$D$31,0))) | G5: =IF(F5="","",IF('Eight questions'!P5="A person is affected",1,0)) | H5: =IF(F5="","",IF('Eight questions'!J5="Regulated",3,1)) | I5: =IF(F5="","",MATCH(F5,Lists!$A$37:$A$40,0)) | J5: =IF(I5="","",MIN(4,MAX(I5+G5,H5))) | K5: =IF(J5="","",INDEX(Lists!$A$37:$A$40,J5)) | L5: =IF(J5="","",INDEX(Lists!$C$37:$C$40,J5)) | W5: =IF(COUNTA(P5:U5)=0,"",IF(COUNTIF(P5:U5,"Not met")>0,"Blocked",IF(COUNTIF(P5:U5,"In progress")>0,"In progress",IF(COUNTA(P5:U5)<6,"Incomplete","Passed"))))
A6: =IF(Register!A6="","",Register!A6) | B6: =IF(Register!C6="","",Register!C6) | C6: =IF('Eight questions'!O6="","",'Eight questions'!O6) | D6: =IF('Eight questions'!F6="","",'Eight questions'!F6) | E6: =IF(D6="","",IF(VALUE(LEFT(D6,1))<=2,"1-2",IF(VALUE(LEFT(D6,1))=3,"3","4-5"))) | F6: =IF(OR(C6="",E6=""),"",INDEX(Lists!$B$32:$D$34,MATCH(C6,Lists!$A$32:$A$34,0),MATCH(E6,Lists!$B$31:$D$31,0))) | G6: =IF(F6="","",IF('Eight questions'!P6="A person is affected",1,0)) | H6: =IF(F6="","",IF('Eight questions'!J6="Regulated",3,1)) | I6: =IF(F6="","",MATCH(F6,Lists!$A$37:$A$40,0)) | J6: =IF(I6="","",MIN(4,MAX(I6+G6,H6))) | K6: =IF(J6="","",INDEX(Lists!$A$37:$A$40,J6)) | L6: =IF(J6="","",INDEX(Lists!$C$37:$C$40,J6)) | W6: =IF(COUNTA(P6:U6)=0,"",IF(COUNTIF(P6:U6,"Not met")>0,"Blocked",IF(COUNTIF(P6:U6,"In progress")>0,"In progress",IF(COUNTA(P6:U6)<6,"Incomplete","Passed"))))
A7: =IF(Register!A7="","",Register!A7) | B7: =IF(Register!C7="","",Register!C7) | C7: =IF('Eight questions'!O7="","",'Eight questions'!O7) | D7: =IF('Eight questions'!F7="","",'Eight questions'!F7) | E7: =IF(D7="","",IF(VALUE(LEFT(D7,1))<=2,"1-2",IF(VALUE(LEFT(D7,1))=3,"3","4-5"))) | F7: =IF(OR(C7="",E7=""),"",INDEX(Lists!$B$32:$D$34,MATCH(C7,Lists!$A$32:$A$34,0),MATCH(E7,Lists!$B$31:$D$31,0))) | G7: =IF(F7="","",IF('Eight questions'!P7="A person is affected",1,0)) | H7: =IF(F7="","",IF('Eight questions'!J7="Regulated",3,1)) | I7: =IF(F7="","",MATCH(F7,Lists!$A$37:$A$40,0)) | J7: =IF(I7="","",MIN(4,MAX(I7+G7,H7))) | K7: =IF(J7="","",INDEX(Lists!$A$37:$A$40,J7)) | L7: =IF(J7="","",INDEX(Lists!$C$37:$C$40,J7)) | W7: =IF(COUNTA(P7:U7)=0,"",IF(COUNTIF(P7:U7,"Not met")>0,"Blocked",IF(COUNTIF(P7:U7,"In progress")>0,"In progress",IF(COUNTA(P7:U7)<6,"Incomplete","Passed"))))
A8: =IF(Register!A8="","",Register!A8) | B8: =IF(Register!C8="","",Register!C8) | C8: =IF('Eight questions'!O8="","",'Eight questions'!O8) | D8: =IF('Eight questions'!F8="","",'Eight questions'!F8) | E8: =IF(D8="","",IF(VALUE(LEFT(D8,1))<=2,"1-2",IF(VALUE(LEFT(D8,1))=3,"3","4-5"))) | F8: =IF(OR(C8="",E8=""),"",INDEX(Lists!$B$32:$D$34,MATCH(C8,Lists!$A$32:$A$34,0),MATCH(E8,Lists!$B$31:$D$31,0))) | G8: =IF(F8="","",IF('Eight questions'!P8="A person is affected",1,0)) | H8: =IF(F8="","",IF('Eight questions'!J8="Regulated",3,1)) | I8: =IF(F8="","",MATCH(F8,Lists!$A$37:$A$40,0)) | J8: =IF(I8="","",MIN(4,MAX(I8+G8,H8))) | K8: =IF(J8="","",INDEX(Lists!$A$37:$A$40,J8)) | L8: =IF(J8="","",INDEX(Lists!$C$37:$C$40,J8)) | W8: =IF(COUNTA(P8:U8)=0,"",IF(COUNTIF(P8:U8,"Not met")>0,"Blocked",IF(COUNTIF(P8:U8,"In progress")>0,"In progress",IF(COUNTA(P8:U8)<6,"Incomplete","Passed"))))
A9: =IF(Register!A9="","",Register!A9) | B9: =IF(Register!C9="","",Register!C9) | C9: =IF('Eight questions'!O9="","",'Eight questions'!O9) | D9: =IF('Eight questions'!F9="","",'Eight questions'!F9) | E9: =IF(D9="","",IF(VALUE(LEFT(D9,1))<=2,"1-2",IF(VALUE(LEFT(D9,1))=3,"3","4-5"))) | F9: =IF(OR(C9="",E9=""),"",INDEX(Lists!$B$32:$D$34,MATCH(C9,Lists!$A$32:$A$34,0),MATCH(E9,Lists!$B$31:$D$31,0))) | G9: =IF(F9="","",IF('Eight questions'!P9="A person is affected",1,0)) | H9: =IF(F9="","",IF('Eight questions'!J9="Regulated",3,1)) | I9: =IF(F9="","",MATCH(F9,Lists!$A$37:$A$40,0)) | J9: =IF(I9="","",MIN(4,MAX(I9+G9,H9))) | K9: =IF(J9="","",INDEX(Lists!$A$37:$A$40,J9)) | L9: =IF(J9="","",INDEX(Lists!$C$37:$C$40,J9)) | W9: =IF(COUNTA(P9:U9)=0,"",IF(COUNTIF(P9:U9,"Not met")>0,"Blocked",IF(COUNTIF(P9:U9,"In progress")>0,"In progress",IF(COUNTA(P9:U9)<6,"Incomplete","Passed"))))
A10: =IF(Register!A10="","",Register!A10) | B10: =IF(Register!C10="","",Register!C10) | C10: =IF('Eight questions'!O10="","",'Eight questions'!O10) | D10: =IF('Eight questions'!F10="","",'Eight questions'!F10) | E10: =IF(D10="","",IF(VALUE(LEFT(D10,1))<=2,"1-2",IF(VALUE(LEFT(D10,1))=3,"3","4-5"))) | F10: =IF(OR(C10="",E10=""),"",INDEX(Lists!$B$32:$D$34,MATCH(C10,Lists!$A$32:$A$34,0),MATCH(E10,Lists!$B$31:$D$31,0))) | G10: =IF(F10="","",IF('Eight questions'!P10="A person is affected",1,0)) | H10: =IF(F10="","",IF('Eight questions'!J10="Regulated",3,1)) | I10: =IF(F10="","",MATCH(F10,Lists!$A$37:$A$40,0)) | J10: =IF(I10="","",MIN(4,MAX(I10+G10,H10))) | K10: =IF(J10="","",INDEX(Lists!$A$37:$A$40,J10)) | L10: =IF(J10="","",INDEX(Lists!$C$37:$C$40,J10)) | W10: =IF(COUNTA(P10:U10)=0,"",IF(COUNTIF(P10:U10,"Not met")>0,"Blocked",IF(COUNTIF(P10:U10,"In progress")>0,"In progress",IF(COUNTA(P10:U10)<6,"Incomplete","Passed"))))
A11: =IF(Register!A11="","",Register!A11) | B11: =IF(Register!C11="","",Register!C11) | C11: =IF('Eight questions'!O11="","",'Eight questions'!O11) | D11: =IF('Eight questions'!F11="","",'Eight questions'!F11) | E11: =IF(D11="","",IF(VALUE(LEFT(D11,1))<=2,"1-2",IF(VALUE(LEFT(D11,1))=3,"3","4-5"))) | F11: =IF(OR(C11="",E11=""),"",INDEX(Lists!$B$32:$D$34,MATCH(C11,Lists!$A$32:$A$34,0),MATCH(E11,Lists!$B$31:$D$31,0))) | G11: =IF(F11="","",IF('Eight questions'!P11="A person is affected",1,0)) | H11: =IF(F11="","",IF('Eight questions'!J11="Regulated",3,1)) | I11: =IF(F11="","",MATCH(F11,Lists!$A$37:$A$40,0)) | J11: =IF(I11="","",MIN(4,MAX(I11+G11,H11))) | K11: =IF(J11="","",INDEX(Lists!$A$37:$A$40,J11)) | L11: =IF(J11="","",INDEX(Lists!$C$37:$C$40,J11)) | W11: =IF(COUNTA(P11:U11)=0,"",IF(COUNTIF(P11:U11,"Not met")>0,"Blocked",IF(COUNTIF(P11:U11,"In progress")>0,"In progress",IF(COUNTA(P11:U11)<6,"Incomplete","Passed"))))
A12: =IF(Register!A12="","",Register!A12) | B12: =IF(Register!C12="","",Register!C12) | C12: =IF('Eight questions'!O12="","",'Eight questions'!O12) | D12: =IF('Eight questions'!F12="","",'Eight questions'!F12) | E12: =IF(D12="","",IF(VALUE(LEFT(D12,1))<=2,"1-2",IF(VALUE(LEFT(D12,1))=3,"3","4-5"))) | F12: =IF(OR(C12="",E12=""),"",INDEX(Lists!$B$32:$D$34,MATCH(C12,Lists!$A$32:$A$34,0),MATCH(E12,Lists!$B$31:$D$31,0))) | G12: =IF(F12="","",IF('Eight questions'!P12="A person is affected",1,0)) | H12: =IF(F12="","",IF('Eight questions'!J12="Regulated",3,1)) | I12: =IF(F12="","",MATCH(F12,Lists!$A$37:$A$40,0)) | J12: =IF(I12="","",MIN(4,MAX(I12+G12,H12))) | K12: =IF(J12="","",INDEX(Lists!$A$37:$A$40,J12)) | L12: =IF(J12="","",INDEX(Lists!$C$37:$C$40,J12)) | W12: =IF(COUNTA(P12:U12)=0,"",IF(COUNTIF(P12:U12,"Not met")>0,"Blocked",IF(COUNTIF(P12:U12,"In progress")>0,"In progress",IF(COUNTA(P12:U12)<6,"Incomplete","Passed"))))
A13: =IF(Register!A13="","",Register!A13) | B13: =IF(Register!C13="","",Register!C13) | C13: =IF('Eight questions'!O13="","",'Eight questions'!O13) | D13: =IF('Eight questions'!F13="","",'Eight questions'!F13) | E13: =IF(D13="","",IF(VALUE(LEFT(D13,1))<=2,"1-2",IF(VALUE(LEFT(D13,1))=3,"3","4-5"))) | F13: =IF(OR(C13="",E13=""),"",INDEX(Lists!$B$32:$D$34,MATCH(C13,Lists!$A$32:$A$34,0),MATCH(E13,Lists!$B$31:$D$31,0))) | G13: =IF(F13="","",IF('Eight questions'!P13="A person is affected",1,0)) | H13: =IF(F13="","",IF('Eight questions'!J13="Regulated",3,1)) | I13: =IF(F13="","",MATCH(F13,Lists!$A$37:$A$40,0)) | J13: =IF(I13="","",MIN(4,MAX(I13+G13,H13))) | K13: =IF(J13="","",INDEX(Lists!$A$37:$A$40,J13)) | L13: =IF(J13="","",INDEX(Lists!$C$37:$C$40,J13)) | W13: =IF(COUNTA(P13:U13)=0,"",IF(COUNTIF(P13:U13,"Not met")>0,"Blocked",IF(COUNTIF(P13:U13,"In progress")>0,"In progress",IF(COUNTA(P13:U13)<6,"Incomplete","Passed"))))
A14: =IF(Register!A14="","",Register!A14) | B14: =IF(Register!C14="","",Register!C14) | C14: =IF('Eight questions'!O14="","",'Eight questions'!O14) | D14: =IF('Eight questions'!F14="","",'Eight questions'!F14) | E14: =IF(D14="","",IF(VALUE(LEFT(D14,1))<=2,"1-2",IF(VALUE(LEFT(D14,1))=3,"3","4-5"))) | F14: =IF(OR(C14="",E14=""),"",INDEX(Lists!$B$32:$D$34,MATCH(C14,Lists!$A$32:$A$34,0),MATCH(E14,Lists!$B$31:$D$31,0))) | G14: =IF(F14="","",IF('Eight questions'!P14="A person is affected",1,0)) | H14: =IF(F14="","",IF('Eight questions'!J14="Regulated",3,1)) | I14: =IF(F14="","",MATCH(F14,Lists!$A$37:$A$40,0)) | J14: =IF(I14="","",MIN(4,MAX(I14+G14,H14))) | K14: =IF(J14="","",INDEX(Lists!$A$37:$A$40,J14)) | L14: =IF(J14="","",INDEX(Lists!$C$37:$C$40,J14)) | W14: =IF(COUNTA(P14:U14)=0,"",IF(COUNTIF(P14:U14,"Not met")>0,"Blocked",IF(COUNTIF(P14:U14,"In progress")>0,"In progress",IF(COUNTA(P14:U14)<6,"Incomplete","Passed"))))
A15: =IF(Register!A15="","",Register!A15) | B15: =IF(Register!C15="","",Register!C15) | C15: =IF('Eight questions'!O15="","",'Eight questions'!O15) | D15: =IF('Eight questions'!F15="","",'Eight questions'!F15) | E15: =IF(D15="","",IF(VALUE(LEFT(D15,1))<=2,"1-2",IF(VALUE(LEFT(D15,1))=3,"3","4-5"))) | F15: =IF(OR(C15="",E15=""),"",INDEX(Lists!$B$32:$D$34,MATCH(C15,Lists!$A$32:$A$34,0),MATCH(E15,Lists!$B$31:$D$31,0))) | G15: =IF(F15="","",IF('Eight questions'!P15="A person is affected",1,0)) | H15: =IF(F15="","",IF('Eight questions'!J15="Regulated",3,1)) | I15: =IF(F15="","",MATCH(F15,Lists!$A$37:$A$40,0)) | J15: =IF(I15="","",MIN(4,MAX(I15+G15,H15))) | K15: =IF(J15="","",INDEX(Lists!$A$37:$A$40,J15)) | L15: =IF(J15="","",INDEX(Lists!$C$37:$C$40,J15)) | W15: =IF(COUNTA(P15:U15)=0,"",IF(COUNTIF(P15:U15,"Not met")>0,"Blocked",IF(COUNTIF(P15:U15,"In progress")>0,"In progress",IF(COUNTA(P15:U15)<6,"Incomplete","Passed"))))
